{
 "cells": [
  {
   "cell_type": "code",
   "execution_count": 6,
   "metadata": {},
   "outputs": [
    {
     "name": "stdout",
     "output_type": "stream",
     "text": [
      "Requirement already satisfied: keras in c:\\programdata\\anaconda3\\lib\\site-packages (2.4.3)\n",
      "Requirement already satisfied: scipy>=0.14 in c:\\programdata\\anaconda3\\lib\\site-packages (from keras) (1.4.1)\n",
      "Requirement already satisfied: pyyaml in c:\\programdata\\anaconda3\\lib\\site-packages (from keras) (5.3)\n",
      "Requirement already satisfied: numpy>=1.9.1 in c:\\programdata\\anaconda3\\lib\\site-packages (from keras) (1.18.5)\n",
      "Requirement already satisfied: h5py in c:\\programdata\\anaconda3\\lib\\site-packages (from keras) (2.10.0)\n",
      "Requirement already satisfied: six in c:\\programdata\\anaconda3\\lib\\site-packages (from h5py->keras) (1.15.0)\n",
      "Note: you may need to restart the kernel to use updated packages.\n"
     ]
    }
   ],
   "source": [
    "pip install keras"
   ]
  },
  {
   "cell_type": "code",
   "execution_count": 8,
   "metadata": {},
   "outputs": [
    {
     "name": "stdout",
     "output_type": "stream",
     "text": [
      "Requirement already satisfied: tensorflow in c:\\programdata\\anaconda3\\lib\\site-packages (2.0.0)\n",
      "Requirement already satisfied: termcolor>=1.1.0 in c:\\programdata\\anaconda3\\lib\\site-packages (from tensorflow) (1.1.0)\n",
      "Requirement already satisfied: wrapt>=1.11.1 in c:\\programdata\\anaconda3\\lib\\site-packages (from tensorflow) (1.12.1)\n",
      "Requirement already satisfied: grpcio>=1.8.6 in c:\\programdata\\anaconda3\\lib\\site-packages (from tensorflow) (1.30.0)\n",
      "Requirement already satisfied: numpy<2.0,>=1.16.0 in c:\\programdata\\anaconda3\\lib\\site-packages (from tensorflow) (1.18.5)\n",
      "Requirement already satisfied: six>=1.10.0 in c:\\programdata\\anaconda3\\lib\\site-packages (from tensorflow) (1.15.0)\n",
      "Processing c:\\users\\ccmedia\\appdata\\local\\pip\\cache\\wheels\\21\\7f\\02\\420f32a803f7d0967b48dd823da3f558c5166991bfd204eef3\\gast-0.2.2-py3-none-any.whl\n",
      "Requirement already satisfied: absl-py>=0.7.0 in c:\\programdata\\anaconda3\\lib\\site-packages (from tensorflow) (0.9.0)\n",
      "Requirement already satisfied: opt-einsum>=2.3.2 in c:\\programdata\\anaconda3\\lib\\site-packages (from tensorflow) (3.2.1)\n",
      "Requirement already satisfied: keras-applications>=1.0.8 in c:\\programdata\\anaconda3\\lib\\site-packages (from tensorflow) (1.0.8)\n",
      "Collecting tensorflow-estimator<2.1.0,>=2.0.0\n",
      "  Using cached tensorflow_estimator-2.0.1-py2.py3-none-any.whl (449 kB)\n",
      "Requirement already satisfied: protobuf>=3.6.1 in c:\\programdata\\anaconda3\\lib\\site-packages (from tensorflow) (3.12.2)\n",
      "Requirement already satisfied: google-pasta>=0.1.6 in c:\\programdata\\anaconda3\\lib\\site-packages (from tensorflow) (0.2.0)\n",
      "Requirement already satisfied: keras-preprocessing>=1.0.5 in c:\\programdata\\anaconda3\\lib\\site-packages (from tensorflow) (1.1.2)\n",
      "Requirement already satisfied: wheel>=0.26 in c:\\programdata\\anaconda3\\lib\\site-packages (from tensorflow) (0.34.2)\n",
      "Requirement already satisfied: tensorboard<2.1.0,>=2.0.0 in c:\\programdata\\anaconda3\\lib\\site-packages (from tensorflow) (2.0.2)\n",
      "Requirement already satisfied: astor>=0.6.0 in c:\\programdata\\anaconda3\\lib\\site-packages (from tensorflow) (0.8.1)\n",
      "Requirement already satisfied: h5py in c:\\programdata\\anaconda3\\lib\\site-packages (from keras-applications>=1.0.8->tensorflow) (2.10.0)\n",
      "Requirement already satisfied: setuptools in c:\\programdata\\anaconda3\\lib\\site-packages (from protobuf>=3.6.1->tensorflow) (45.2.0.post20200210)\n",
      "Requirement already satisfied: google-auth<2,>=1.6.3 in c:\\programdata\\anaconda3\\lib\\site-packages (from tensorboard<2.1.0,>=2.0.0->tensorflow) (1.19.0)\n",
      "Requirement already satisfied: google-auth-oauthlib<0.5,>=0.4.1 in c:\\programdata\\anaconda3\\lib\\site-packages (from tensorboard<2.1.0,>=2.0.0->tensorflow) (0.4.1)\n",
      "Requirement already satisfied: werkzeug>=0.11.15 in c:\\programdata\\anaconda3\\lib\\site-packages (from tensorboard<2.1.0,>=2.0.0->tensorflow) (1.0.0)\n",
      "Requirement already satisfied: requests<3,>=2.21.0 in c:\\programdata\\anaconda3\\lib\\site-packages (from tensorboard<2.1.0,>=2.0.0->tensorflow) (2.22.0)\n",
      "Requirement already satisfied: markdown>=2.6.8 in c:\\programdata\\anaconda3\\lib\\site-packages (from tensorboard<2.1.0,>=2.0.0->tensorflow) (3.2.2)\n",
      "Requirement already satisfied: pyasn1-modules>=0.2.1 in c:\\programdata\\anaconda3\\lib\\site-packages (from google-auth<2,>=1.6.3->tensorboard<2.1.0,>=2.0.0->tensorflow) (0.2.8)\n",
      "Requirement already satisfied: rsa<5,>=3.1.4; python_version >= \"3\" in c:\\programdata\\anaconda3\\lib\\site-packages (from google-auth<2,>=1.6.3->tensorboard<2.1.0,>=2.0.0->tensorflow) (4.6)\n",
      "Requirement already satisfied: cachetools<5.0,>=2.0.0 in c:\\programdata\\anaconda3\\lib\\site-packages (from google-auth<2,>=1.6.3->tensorboard<2.1.0,>=2.0.0->tensorflow) (4.1.1)\n",
      "Requirement already satisfied: requests-oauthlib>=0.7.0 in c:\\programdata\\anaconda3\\lib\\site-packages (from google-auth-oauthlib<0.5,>=0.4.1->tensorboard<2.1.0,>=2.0.0->tensorflow) (1.3.0)\n",
      "Requirement already satisfied: urllib3!=1.25.0,!=1.25.1,<1.26,>=1.21.1 in c:\\programdata\\anaconda3\\lib\\site-packages (from requests<3,>=2.21.0->tensorboard<2.1.0,>=2.0.0->tensorflow) (1.25.8)\n",
      "Requirement already satisfied: chardet<3.1.0,>=3.0.2 in c:\\programdata\\anaconda3\\lib\\site-packages (from requests<3,>=2.21.0->tensorboard<2.1.0,>=2.0.0->tensorflow) (3.0.4)\n",
      "Requirement already satisfied: certifi>=2017.4.17 in c:\\programdata\\anaconda3\\lib\\site-packages (from requests<3,>=2.21.0->tensorboard<2.1.0,>=2.0.0->tensorflow) (2019.11.28)\n",
      "Requirement already satisfied: idna<2.9,>=2.5 in c:\\programdata\\anaconda3\\lib\\site-packages (from requests<3,>=2.21.0->tensorboard<2.1.0,>=2.0.0->tensorflow) (2.8)\n",
      "Requirement already satisfied: importlib-metadata; python_version < \"3.8\" in c:\\programdata\\anaconda3\\lib\\site-packages (from markdown>=2.6.8->tensorboard<2.1.0,>=2.0.0->tensorflow) (1.5.0)\n",
      "Requirement already satisfied: pyasn1<0.5.0,>=0.4.6 in c:\\programdata\\anaconda3\\lib\\site-packages (from pyasn1-modules>=0.2.1->google-auth<2,>=1.6.3->tensorboard<2.1.0,>=2.0.0->tensorflow) (0.4.8)\n",
      "Requirement already satisfied: oauthlib>=3.0.0 in c:\\programdata\\anaconda3\\lib\\site-packages (from requests-oauthlib>=0.7.0->google-auth-oauthlib<0.5,>=0.4.1->tensorboard<2.1.0,>=2.0.0->tensorflow) (3.1.0)\n",
      "Requirement already satisfied: zipp>=0.5 in c:\\programdata\\anaconda3\\lib\\site-packages (from importlib-metadata; python_version < \"3.8\"->markdown>=2.6.8->tensorboard<2.1.0,>=2.0.0->tensorflow) (2.2.0)\n",
      "Installing collected packages: gast, tensorflow-estimator\n",
      "  Attempting uninstall: gast\n",
      "    Found existing installation: gast 0.3.3\n",
      "    Uninstalling gast-0.3.3:\n",
      "      Successfully uninstalled gast-0.3.3\n",
      "  Attempting uninstall: tensorflow-estimator\n",
      "    Found existing installation: tensorflow-estimator 2.3.0\n",
      "    Uninstalling tensorflow-estimator-2.3.0:\n",
      "      Successfully uninstalled tensorflow-estimator-2.3.0\n",
      "Successfully installed gast-0.2.2 tensorflow-estimator-2.0.1\n",
      "Note: you may need to restart the kernel to use updated packages.\n"
     ]
    }
   ],
   "source": [
    "pip install tensorflow"
   ]
  },
  {
   "cell_type": "code",
   "execution_count": 3,
   "metadata": {},
   "outputs": [
    {
     "name": "stdout",
     "output_type": "stream",
     "text": [
      "Requirement already up-to-date: pip in c:\\programdata\\anaconda3\\lib\\site-packages (20.2.1)\n",
      "Note: you may need to restart the kernel to use updated packages.\n"
     ]
    }
   ],
   "source": [
    "pip install --upgrade pip"
   ]
  },
  {
   "cell_type": "code",
   "execution_count": 10,
   "metadata": {},
   "outputs": [],
   "source": [
    "import tensorflow as tf\n"
   ]
  },
  {
   "cell_type": "code",
   "execution_count": 11,
   "metadata": {},
   "outputs": [
    {
     "name": "stderr",
     "output_type": "stream",
     "text": [
      "ERROR:root:Internal Python error in the inspect module.\n",
      "Below is the traceback from this internal error.\n",
      "\n",
      "ERROR:root:Internal Python error in the inspect module.\n",
      "Below is the traceback from this internal error.\n",
      "\n"
     ]
    },
    {
     "name": "stdout",
     "output_type": "stream",
     "text": [
      "Traceback (most recent call last):\n",
      "  File \"C:\\ProgramData\\Anaconda3\\lib\\site-packages\\keras\\__init__.py\", line 3, in <module>\n",
      "    from tensorflow.keras.layers.experimental.preprocessing import RandomRotation\n",
      "ModuleNotFoundError: No module named 'tensorflow.keras.layers.experimental.preprocessing'\n",
      "\n",
      "During handling of the above exception, another exception occurred:\n",
      "\n",
      "Traceback (most recent call last):\n",
      "  File \"C:\\ProgramData\\Anaconda3\\lib\\site-packages\\IPython\\core\\interactiveshell.py\", line 3331, in run_code\n",
      "    exec(code_obj, self.user_global_ns, self.user_ns)\n",
      "  File \"<ipython-input-11-4c646f272b35>\", line 2, in <module>\n",
      "    from keras.utils import np_utils\n",
      "  File \"C:\\ProgramData\\Anaconda3\\lib\\site-packages\\keras\\__init__.py\", line 6, in <module>\n",
      "    'Keras requires TensorFlow 2.2 or higher. '\n",
      "ImportError: Keras requires TensorFlow 2.2 or higher. Install TensorFlow via `pip install tensorflow`\n",
      "\n",
      "During handling of the above exception, another exception occurred:\n",
      "\n",
      "Traceback (most recent call last):\n",
      "  File \"C:\\ProgramData\\Anaconda3\\lib\\site-packages\\IPython\\core\\interactiveshell.py\", line 2044, in showtraceback\n",
      "    stb = value._render_traceback_()\n",
      "AttributeError: 'ImportError' object has no attribute '_render_traceback_'\n",
      "\n",
      "During handling of the above exception, another exception occurred:\n",
      "\n",
      "Traceback (most recent call last):\n",
      "  File \"C:\\ProgramData\\Anaconda3\\lib\\site-packages\\IPython\\core\\ultratb.py\", line 1151, in get_records\n",
      "    return _fixed_getinnerframes(etb, number_of_lines_of_context, tb_offset)\n",
      "  File \"C:\\ProgramData\\Anaconda3\\lib\\site-packages\\IPython\\core\\ultratb.py\", line 319, in wrapped\n",
      "    return f(*args, **kwargs)\n",
      "  File \"C:\\ProgramData\\Anaconda3\\lib\\site-packages\\IPython\\core\\ultratb.py\", line 353, in _fixed_getinnerframes\n",
      "    records = fix_frame_records_filenames(inspect.getinnerframes(etb, context))\n",
      "  File \"C:\\ProgramData\\Anaconda3\\lib\\inspect.py\", line 1502, in getinnerframes\n",
      "    frameinfo = (tb.tb_frame,) + getframeinfo(tb, context)\n",
      "  File \"C:\\ProgramData\\Anaconda3\\lib\\inspect.py\", line 1460, in getframeinfo\n",
      "    filename = getsourcefile(frame) or getfile(frame)\n",
      "  File \"C:\\ProgramData\\Anaconda3\\lib\\inspect.py\", line 696, in getsourcefile\n",
      "    if getattr(getmodule(object, filename), '__loader__', None) is not None:\n",
      "  File \"C:\\ProgramData\\Anaconda3\\lib\\inspect.py\", line 733, in getmodule\n",
      "    if ismodule(module) and hasattr(module, '__file__'):\n",
      "  File \"C:\\ProgramData\\Anaconda3\\lib\\site-packages\\tensorflow\\__init__.py\", line 50, in __getattr__\n",
      "    module = self._load()\n",
      "  File \"C:\\ProgramData\\Anaconda3\\lib\\site-packages\\tensorflow\\__init__.py\", line 44, in _load\n",
      "    module = _importlib.import_module(self.__name__)\n",
      "  File \"C:\\ProgramData\\Anaconda3\\lib\\importlib\\__init__.py\", line 127, in import_module\n",
      "    return _bootstrap._gcd_import(name[level:], package, level)\n",
      "  File \"<frozen importlib._bootstrap>\", line 1006, in _gcd_import\n",
      "  File \"<frozen importlib._bootstrap>\", line 983, in _find_and_load\n",
      "  File \"<frozen importlib._bootstrap>\", line 965, in _find_and_load_unlocked\n",
      "ModuleNotFoundError: No module named 'tensorflow_core.estimator'\n",
      "Traceback (most recent call last):\n",
      "  File \"C:\\ProgramData\\Anaconda3\\lib\\site-packages\\keras\\__init__.py\", line 3, in <module>\n",
      "    from tensorflow.keras.layers.experimental.preprocessing import RandomRotation\n",
      "ModuleNotFoundError: No module named 'tensorflow.keras.layers.experimental.preprocessing'\n",
      "\n",
      "During handling of the above exception, another exception occurred:\n",
      "\n",
      "Traceback (most recent call last):\n",
      "  File \"C:\\ProgramData\\Anaconda3\\lib\\site-packages\\IPython\\core\\interactiveshell.py\", line 3331, in run_code\n",
      "    exec(code_obj, self.user_global_ns, self.user_ns)\n",
      "  File \"<ipython-input-11-4c646f272b35>\", line 2, in <module>\n",
      "    from keras.utils import np_utils\n",
      "  File \"C:\\ProgramData\\Anaconda3\\lib\\site-packages\\keras\\__init__.py\", line 6, in <module>\n",
      "    'Keras requires TensorFlow 2.2 or higher. '\n",
      "ImportError: Keras requires TensorFlow 2.2 or higher. Install TensorFlow via `pip install tensorflow`\n",
      "\n",
      "During handling of the above exception, another exception occurred:\n",
      "\n",
      "Traceback (most recent call last):\n",
      "  File \"C:\\ProgramData\\Anaconda3\\lib\\site-packages\\IPython\\core\\interactiveshell.py\", line 2044, in showtraceback\n",
      "    stb = value._render_traceback_()\n",
      "AttributeError: 'ImportError' object has no attribute '_render_traceback_'\n",
      "\n",
      "During handling of the above exception, another exception occurred:\n",
      "\n",
      "Traceback (most recent call last):\n",
      "  File \"C:\\ProgramData\\Anaconda3\\lib\\site-packages\\IPython\\core\\interactiveshell.py\", line 3254, in run_ast_nodes\n",
      "    if (await self.run_code(code, result,  async_=asy)):\n",
      "  File \"C:\\ProgramData\\Anaconda3\\lib\\site-packages\\IPython\\core\\interactiveshell.py\", line 3348, in run_code\n",
      "    self.showtraceback(running_compiled_code=True)\n",
      "  File \"C:\\ProgramData\\Anaconda3\\lib\\site-packages\\IPython\\core\\interactiveshell.py\", line 2047, in showtraceback\n",
      "    value, tb, tb_offset=tb_offset)\n",
      "  File \"C:\\ProgramData\\Anaconda3\\lib\\site-packages\\IPython\\core\\ultratb.py\", line 1418, in structured_traceback\n",
      "    self, etype, value, tb, tb_offset, number_of_lines_of_context)\n",
      "  File \"C:\\ProgramData\\Anaconda3\\lib\\site-packages\\IPython\\core\\ultratb.py\", line 1318, in structured_traceback\n",
      "    self, etype, value, tb, tb_offset, number_of_lines_of_context\n",
      "  File \"C:\\ProgramData\\Anaconda3\\lib\\site-packages\\IPython\\core\\ultratb.py\", line 1186, in structured_traceback\n",
      "    formatted_exceptions += self.prepare_chained_exception_message(evalue.__cause__)\n",
      "TypeError: can only concatenate str (not \"list\") to str\n",
      "\n",
      "During handling of the above exception, another exception occurred:\n",
      "\n",
      "Traceback (most recent call last):\n",
      "  File \"C:\\ProgramData\\Anaconda3\\lib\\site-packages\\IPython\\core\\interactiveshell.py\", line 2044, in showtraceback\n",
      "    stb = value._render_traceback_()\n",
      "AttributeError: 'TypeError' object has no attribute '_render_traceback_'\n",
      "\n",
      "During handling of the above exception, another exception occurred:\n",
      "\n",
      "Traceback (most recent call last):\n",
      "  File \"C:\\ProgramData\\Anaconda3\\lib\\site-packages\\IPython\\core\\ultratb.py\", line 1151, in get_records\n",
      "    return _fixed_getinnerframes(etb, number_of_lines_of_context, tb_offset)\n",
      "  File \"C:\\ProgramData\\Anaconda3\\lib\\site-packages\\IPython\\core\\ultratb.py\", line 319, in wrapped\n",
      "    return f(*args, **kwargs)\n",
      "  File \"C:\\ProgramData\\Anaconda3\\lib\\site-packages\\IPython\\core\\ultratb.py\", line 353, in _fixed_getinnerframes\n",
      "    records = fix_frame_records_filenames(inspect.getinnerframes(etb, context))\n",
      "  File \"C:\\ProgramData\\Anaconda3\\lib\\inspect.py\", line 1502, in getinnerframes\n",
      "    frameinfo = (tb.tb_frame,) + getframeinfo(tb, context)\n",
      "  File \"C:\\ProgramData\\Anaconda3\\lib\\inspect.py\", line 1460, in getframeinfo\n",
      "    filename = getsourcefile(frame) or getfile(frame)\n",
      "  File \"C:\\ProgramData\\Anaconda3\\lib\\inspect.py\", line 696, in getsourcefile\n",
      "    if getattr(getmodule(object, filename), '__loader__', None) is not None:\n",
      "  File \"C:\\ProgramData\\Anaconda3\\lib\\inspect.py\", line 733, in getmodule\n",
      "    if ismodule(module) and hasattr(module, '__file__'):\n",
      "  File \"C:\\ProgramData\\Anaconda3\\lib\\site-packages\\tensorflow\\__init__.py\", line 50, in __getattr__\n",
      "    module = self._load()\n",
      "  File \"C:\\ProgramData\\Anaconda3\\lib\\site-packages\\tensorflow\\__init__.py\", line 44, in _load\n",
      "    module = _importlib.import_module(self.__name__)\n",
      "  File \"C:\\ProgramData\\Anaconda3\\lib\\importlib\\__init__.py\", line 127, in import_module\n",
      "    return _bootstrap._gcd_import(name[level:], package, level)\n",
      "  File \"<frozen importlib._bootstrap>\", line 1006, in _gcd_import\n",
      "  File \"<frozen importlib._bootstrap>\", line 983, in _find_and_load\n",
      "  File \"<frozen importlib._bootstrap>\", line 965, in _find_and_load_unlocked\n",
      "ModuleNotFoundError: No module named 'tensorflow_core.estimator'\n"
     ]
    },
    {
     "ename": "TypeError",
     "evalue": "can only concatenate str (not \"list\") to str",
     "output_type": "error",
     "traceback": [
      "\u001b[1;31m-----------------------------------------------------------------------\u001b[0m",
      "\u001b[1;31mModuleNotFoundError\u001b[0m                   Traceback (most recent call last)",
      "\u001b[1;32mC:\\ProgramData\\Anaconda3\\lib\\site-packages\\keras\\__init__.py\u001b[0m in \u001b[0;36m<module>\u001b[1;34m\u001b[0m\n\u001b[0;32m      2\u001b[0m \u001b[1;32mtry\u001b[0m\u001b[1;33m:\u001b[0m\u001b[1;33m\u001b[0m\u001b[1;33m\u001b[0m\u001b[0m\n\u001b[1;32m----> 3\u001b[1;33m     \u001b[1;32mfrom\u001b[0m \u001b[0mtensorflow\u001b[0m\u001b[1;33m.\u001b[0m\u001b[0mkeras\u001b[0m\u001b[1;33m.\u001b[0m\u001b[0mlayers\u001b[0m\u001b[1;33m.\u001b[0m\u001b[0mexperimental\u001b[0m\u001b[1;33m.\u001b[0m\u001b[0mpreprocessing\u001b[0m \u001b[1;32mimport\u001b[0m \u001b[0mRandomRotation\u001b[0m\u001b[1;33m\u001b[0m\u001b[1;33m\u001b[0m\u001b[0m\n\u001b[0m\u001b[0;32m      4\u001b[0m \u001b[1;32mexcept\u001b[0m \u001b[0mImportError\u001b[0m\u001b[1;33m:\u001b[0m\u001b[1;33m\u001b[0m\u001b[1;33m\u001b[0m\u001b[0m\n",
      "\u001b[1;31mModuleNotFoundError\u001b[0m: No module named 'tensorflow.keras.layers.experimental.preprocessing'",
      "\nDuring handling of the above exception, another exception occurred:\n",
      "\nDuring handling of the above exception, another exception occurred:\n",
      "\u001b[1;31mAttributeError\u001b[0m                        Traceback (most recent call last)",
      "\u001b[1;32mC:\\ProgramData\\Anaconda3\\lib\\site-packages\\IPython\\core\\interactiveshell.py\u001b[0m in \u001b[0;36mshowtraceback\u001b[1;34m(self, exc_tuple, filename, tb_offset, exception_only, running_compiled_code)\u001b[0m\n\u001b[0;32m   2043\u001b[0m                         \u001b[1;31m# in the engines. This should return a list of strings.\u001b[0m\u001b[1;33m\u001b[0m\u001b[1;33m\u001b[0m\u001b[1;33m\u001b[0m\u001b[0m\n\u001b[1;32m-> 2044\u001b[1;33m                         \u001b[0mstb\u001b[0m \u001b[1;33m=\u001b[0m \u001b[0mvalue\u001b[0m\u001b[1;33m.\u001b[0m\u001b[0m_render_traceback_\u001b[0m\u001b[1;33m(\u001b[0m\u001b[1;33m)\u001b[0m\u001b[1;33m\u001b[0m\u001b[1;33m\u001b[0m\u001b[0m\n\u001b[0m\u001b[0;32m   2045\u001b[0m                     \u001b[1;32mexcept\u001b[0m \u001b[0mException\u001b[0m\u001b[1;33m:\u001b[0m\u001b[1;33m\u001b[0m\u001b[1;33m\u001b[0m\u001b[0m\n",
      "\u001b[1;31mAttributeError\u001b[0m: 'ImportError' object has no attribute '_render_traceback_'",
      "\nDuring handling of the above exception, another exception occurred:\n",
      "\u001b[1;31mTypeError\u001b[0m                             Traceback (most recent call last)",
      "\u001b[1;32mC:\\ProgramData\\Anaconda3\\lib\\site-packages\\IPython\\core\\interactiveshell.py\u001b[0m in \u001b[0;36mrun_code\u001b[1;34m(self, code_obj, result, async_)\u001b[0m\n\u001b[0;32m   3346\u001b[0m             \u001b[1;32mif\u001b[0m \u001b[0mresult\u001b[0m \u001b[1;32mis\u001b[0m \u001b[1;32mnot\u001b[0m \u001b[1;32mNone\u001b[0m\u001b[1;33m:\u001b[0m\u001b[1;33m\u001b[0m\u001b[1;33m\u001b[0m\u001b[0m\n\u001b[0;32m   3347\u001b[0m                 \u001b[0mresult\u001b[0m\u001b[1;33m.\u001b[0m\u001b[0merror_in_exec\u001b[0m \u001b[1;33m=\u001b[0m \u001b[0msys\u001b[0m\u001b[1;33m.\u001b[0m\u001b[0mexc_info\u001b[0m\u001b[1;33m(\u001b[0m\u001b[1;33m)\u001b[0m\u001b[1;33m[\u001b[0m\u001b[1;36m1\u001b[0m\u001b[1;33m]\u001b[0m\u001b[1;33m\u001b[0m\u001b[1;33m\u001b[0m\u001b[0m\n\u001b[1;32m-> 3348\u001b[1;33m             \u001b[0mself\u001b[0m\u001b[1;33m.\u001b[0m\u001b[0mshowtraceback\u001b[0m\u001b[1;33m(\u001b[0m\u001b[0mrunning_compiled_code\u001b[0m\u001b[1;33m=\u001b[0m\u001b[1;32mTrue\u001b[0m\u001b[1;33m)\u001b[0m\u001b[1;33m\u001b[0m\u001b[1;33m\u001b[0m\u001b[0m\n\u001b[0m\u001b[0;32m   3349\u001b[0m         \u001b[1;32melse\u001b[0m\u001b[1;33m:\u001b[0m\u001b[1;33m\u001b[0m\u001b[1;33m\u001b[0m\u001b[0m\n\u001b[0;32m   3350\u001b[0m             \u001b[0moutflag\u001b[0m \u001b[1;33m=\u001b[0m \u001b[1;32mFalse\u001b[0m\u001b[1;33m\u001b[0m\u001b[1;33m\u001b[0m\u001b[0m\n",
      "\u001b[1;32mC:\\ProgramData\\Anaconda3\\lib\\site-packages\\IPython\\core\\interactiveshell.py\u001b[0m in \u001b[0;36mshowtraceback\u001b[1;34m(self, exc_tuple, filename, tb_offset, exception_only, running_compiled_code)\u001b[0m\n\u001b[0;32m   2045\u001b[0m                     \u001b[1;32mexcept\u001b[0m \u001b[0mException\u001b[0m\u001b[1;33m:\u001b[0m\u001b[1;33m\u001b[0m\u001b[1;33m\u001b[0m\u001b[0m\n\u001b[0;32m   2046\u001b[0m                         stb = self.InteractiveTB.structured_traceback(etype,\n\u001b[1;32m-> 2047\u001b[1;33m                                             value, tb, tb_offset=tb_offset)\n\u001b[0m\u001b[0;32m   2048\u001b[0m \u001b[1;33m\u001b[0m\u001b[0m\n\u001b[0;32m   2049\u001b[0m                     \u001b[0mself\u001b[0m\u001b[1;33m.\u001b[0m\u001b[0m_showtraceback\u001b[0m\u001b[1;33m(\u001b[0m\u001b[0metype\u001b[0m\u001b[1;33m,\u001b[0m \u001b[0mvalue\u001b[0m\u001b[1;33m,\u001b[0m \u001b[0mstb\u001b[0m\u001b[1;33m)\u001b[0m\u001b[1;33m\u001b[0m\u001b[1;33m\u001b[0m\u001b[0m\n",
      "\u001b[1;32mC:\\ProgramData\\Anaconda3\\lib\\site-packages\\IPython\\core\\ultratb.py\u001b[0m in \u001b[0;36mstructured_traceback\u001b[1;34m(self, etype, value, tb, tb_offset, number_of_lines_of_context)\u001b[0m\n\u001b[0;32m   1416\u001b[0m             \u001b[0mself\u001b[0m\u001b[1;33m.\u001b[0m\u001b[0mtb\u001b[0m \u001b[1;33m=\u001b[0m \u001b[0mtb\u001b[0m\u001b[1;33m\u001b[0m\u001b[1;33m\u001b[0m\u001b[0m\n\u001b[0;32m   1417\u001b[0m         return FormattedTB.structured_traceback(\n\u001b[1;32m-> 1418\u001b[1;33m             self, etype, value, tb, tb_offset, number_of_lines_of_context)\n\u001b[0m\u001b[0;32m   1419\u001b[0m \u001b[1;33m\u001b[0m\u001b[0m\n\u001b[0;32m   1420\u001b[0m \u001b[1;33m\u001b[0m\u001b[0m\n",
      "\u001b[1;32mC:\\ProgramData\\Anaconda3\\lib\\site-packages\\IPython\\core\\ultratb.py\u001b[0m in \u001b[0;36mstructured_traceback\u001b[1;34m(self, etype, value, tb, tb_offset, number_of_lines_of_context)\u001b[0m\n\u001b[0;32m   1316\u001b[0m             \u001b[1;31m# Verbose modes need a full traceback\u001b[0m\u001b[1;33m\u001b[0m\u001b[1;33m\u001b[0m\u001b[1;33m\u001b[0m\u001b[0m\n\u001b[0;32m   1317\u001b[0m             return VerboseTB.structured_traceback(\n\u001b[1;32m-> 1318\u001b[1;33m                 \u001b[0mself\u001b[0m\u001b[1;33m,\u001b[0m \u001b[0metype\u001b[0m\u001b[1;33m,\u001b[0m \u001b[0mvalue\u001b[0m\u001b[1;33m,\u001b[0m \u001b[0mtb\u001b[0m\u001b[1;33m,\u001b[0m \u001b[0mtb_offset\u001b[0m\u001b[1;33m,\u001b[0m \u001b[0mnumber_of_lines_of_context\u001b[0m\u001b[1;33m\u001b[0m\u001b[1;33m\u001b[0m\u001b[0m\n\u001b[0m\u001b[0;32m   1319\u001b[0m             )\n\u001b[0;32m   1320\u001b[0m         \u001b[1;32melif\u001b[0m \u001b[0mmode\u001b[0m \u001b[1;33m==\u001b[0m \u001b[1;34m'Minimal'\u001b[0m\u001b[1;33m:\u001b[0m\u001b[1;33m\u001b[0m\u001b[1;33m\u001b[0m\u001b[0m\n",
      "\u001b[1;32mC:\\ProgramData\\Anaconda3\\lib\\site-packages\\IPython\\core\\ultratb.py\u001b[0m in \u001b[0;36mstructured_traceback\u001b[1;34m(self, etype, evalue, etb, tb_offset, number_of_lines_of_context)\u001b[0m\n\u001b[0;32m   1184\u001b[0m         \u001b[0mexception\u001b[0m \u001b[1;33m=\u001b[0m \u001b[0mself\u001b[0m\u001b[1;33m.\u001b[0m\u001b[0mget_parts_of_chained_exception\u001b[0m\u001b[1;33m(\u001b[0m\u001b[0mevalue\u001b[0m\u001b[1;33m)\u001b[0m\u001b[1;33m\u001b[0m\u001b[1;33m\u001b[0m\u001b[0m\n\u001b[0;32m   1185\u001b[0m         \u001b[1;32mif\u001b[0m \u001b[0mexception\u001b[0m\u001b[1;33m:\u001b[0m\u001b[1;33m\u001b[0m\u001b[1;33m\u001b[0m\u001b[0m\n\u001b[1;32m-> 1186\u001b[1;33m             \u001b[0mformatted_exceptions\u001b[0m \u001b[1;33m+=\u001b[0m \u001b[0mself\u001b[0m\u001b[1;33m.\u001b[0m\u001b[0mprepare_chained_exception_message\u001b[0m\u001b[1;33m(\u001b[0m\u001b[0mevalue\u001b[0m\u001b[1;33m.\u001b[0m\u001b[0m__cause__\u001b[0m\u001b[1;33m)\u001b[0m\u001b[1;33m\u001b[0m\u001b[1;33m\u001b[0m\u001b[0m\n\u001b[0m\u001b[0;32m   1187\u001b[0m             \u001b[0metype\u001b[0m\u001b[1;33m,\u001b[0m \u001b[0mevalue\u001b[0m\u001b[1;33m,\u001b[0m \u001b[0metb\u001b[0m \u001b[1;33m=\u001b[0m \u001b[0mexception\u001b[0m\u001b[1;33m\u001b[0m\u001b[1;33m\u001b[0m\u001b[0m\n\u001b[0;32m   1188\u001b[0m         \u001b[1;32melse\u001b[0m\u001b[1;33m:\u001b[0m\u001b[1;33m\u001b[0m\u001b[1;33m\u001b[0m\u001b[0m\n",
      "\u001b[1;31mTypeError\u001b[0m: can only concatenate str (not \"list\") to str"
     ]
    }
   ],
   "source": [
    "# 0. 사용할 패키지 불러오기\n",
    "from keras.utils import np_utils\n",
    "from keras.datasets import mnist\n",
    "from keras.models import Sequential\n",
    "from keras.layers import Dense, Activation"
   ]
  },
  {
   "cell_type": "code",
   "execution_count": null,
   "metadata": {},
   "outputs": [],
   "source": []
  }
 ],
 "metadata": {
  "kernelspec": {
   "display_name": "Python 3",
   "language": "python",
   "name": "python3"
  },
  "language_info": {
   "codemirror_mode": {
    "name": "ipython",
    "version": 3
   },
   "file_extension": ".py",
   "mimetype": "text/x-python",
   "name": "python",
   "nbconvert_exporter": "python",
   "pygments_lexer": "ipython3",
   "version": "3.7.6"
  }
 },
 "nbformat": 4,
 "nbformat_minor": 4
}
